Workbook
Name Página: 'FMEA - Schumag'!#REF!

Sheet Capa
D1: ArcelorMittal - Sabará Diretoria de Trefilação | N1: CÓDIGO: | P1: DTREF SGI DD 0007
N2: REVISÃO: | P2: 22
N3: DATA REVISÃO: | P3: 45954
N4: PÁGINA: | P4: 1 de 8
D6: INFORMAÇÕES GERAIS
D7: TÍTULO DO DOCUMENTO | H7: Fluxo de Processo, PFMEA e Plano de Controle - Schumag
D8: DESCRIÇÃO DO COMPONENTE | H8: Schumag
D9: NOME/NÚMERO DA PEÇA | H9: Barra Trefilada Industrial
D10: MODELO, ANO(S)/PROGRAMAS | H10: Barras trefiladas para o segmento automotivo
D11: RESPONSÁVEL PELO PROCESSO | H11: Tulio César Nogueira
D12: SETOR | H12: Engenharia de Produto e Processo
D14: EQUIPE GESTORA DO DOCUMENTO
D15: ELABORADOR | H15: Paulo César de Oliveira Vilela
D16: VERIFICADOR | H16: Tulio Cesar Nogueira
D17: VERIFICADOR | H17: Douglas Feijó de Almeida
D18: APROVADOR | H18: Glauco Menezes
D20: EQUIPE PRINCIPAL DE ELABORAÇÃO
D21: Thiago Salles - Tulio Nogueira - Wendell Alex - Ciro Eugenio - Glauco Menezes - Paulo Celso - Carolina Siqueira - Jesuíno Siqueira - Paulo Vilela - Ana Barcelos - Claudio Márcio - Thayna Luiza

Sheet Fluxo Processo Schumag
B1: ArcelorMittal - Sabará Diretoria de Trefilação | L1: CÓDIGO: | N1: =Capa!P1 -> DTREF SGI DD 0007
L2: REVISÃO: | N2: 22 | O2: 11
L3: DATA REVISÃO: | N3: 45954 | O3: 45406
L4: PÁGINA: | N4: 2 de 8
B5: FLUXO DE PROCESSO DE PRODUÇÃO DE BARRAS TREFILADAS
B8: SEQ | C8: OPERAÇÕES | D8: SUB-PROCESSOS | K8: REGISTRO
D9: REC | E9: PCP | F9: SCH | G9: RET | H9: COR | I9: EMB | J9: EXP
B10: 1 | C10: RECEBER E INSPECIONAR FM | K10: NF (SAP)
B11: 2 | C11: ARMAZENAR ROLOS DE FM | K11: Depósito SAP
B12: 3 | C12: PROGRAMAR FABRICAÇÃO | K12: Ordem de Produção / SAP/ MÊS
B13: 4 | C13: ABASTECER MÁQUINA | K13: Ordem de Produção
B14: 5 | C14: PRÉ-ENDIREITAR MATÉRIA PRIMA | K14: Sem Registro
B15: 6 | C15: DECAPAR MATÉRIA PRIMA | K15: Sem Registro
B16: 7 | C16: TREFILAR MATÉRIA PRIMA | K16: Sistema Informatizado - MES
B17: 8 | C17: INSPECIONAR BARRAS POR CORRENTE PARASITA | K17: Registro informatizado
B18: 9 | C18: CORTAR BARRAS - SCHUMAGS | K18: Sem Registro
B19: 10 | C19: ENDIREITAR / POLIR E INPECIONAR BARRAS | K19: Sistema Informatizado - MES
B20: 11 | C20: RETIFICAR BARRAS | K20: Sistema Informatizado - MES
B21: 12 | C21: CORTAR BARRAS (MÁQUINA DE CORTE) | K21: Sistema Informatizado - MES
... B25: 16 | C25: EXPEDIR BARRAS | K25: Sistema Informatizado - NF (SAP)
B28: REC | C28: Recepção de Matéria Prima | G28: Operação
B29: PCP | C29: Programação | G29: Operação e Inspeção
B30: SCH | C30: Máquinas Schumag | G30: Operação e Transporte
B31: RET | C31: Retífica | G31: Estocagem
B32: COR | C32: Corte
B33: EMB | C33: Embalagem
B34: EXP | C34: Expedição

Sheet FMEA - Schumag
D1: ArcelorMittal - Sabará Diretoria de Trefilação | O1: CÓDIGO: | P1: =Capa!P1 -> DTREF SGI DD 0007
O2: REVISÃO: | P2: =Capa!P2 -> 22
O3: DATA REVISÃO: | P3: =Capa!P3 -> 45954
O4: PÁGINA: | P4: 3 de 8
A5: ANÁLISE DOS MODOS E EFEITOS DA FALHA
A6: FMEA DE PROCESSO (PFMEA)
A7: Item | B7: Função | C7: Requisito | D7: Modo de Falha Potencial | E7: Efeitos Potenciais da Falha | F7: Severidade | G7: Classificação | H7: Causa(s) Potenciais / Mecanismo de Falha | I7: Projeto Atual | M7: NPR | N7: Ação Recomendada | O7: Responsabilidade Data de conclusão prevista | P7: Resultado da ação
A8: It | I8: Controles Prevenção | J8: Ocorrência | K8: Controles Detecção | L8: Detecção | P8: Ações realizadas Data de conclusão | Q8: Severidade | R8: Ocorrência | S8: Detecção | T8: NPR
A9: 1 | B9: Receber e inspecionar FM | C9: Manter a rastreabilidade do material | D9: Falta de identificação | E9: Sucateamento de material | F9: 8 | H9: Perda da etiqueta de identificação no manuseio | I9: Exigência de duas etiquetas | J9: 3 | K9: Conferência no recebimento. Rolo a Rolo | L9: 7 | M9: =F9*J9*L9 -> 168
F10: 8 | H10: Lacres rompidos ou etiquetas improvisadas | I10: Exigência de duas etiquetas | J10: 3 | K10: Conferência no recebimento. Rolo a Rolo | L10: 7 | M10: =F10*J10*L10 -> 168
D11: Perda de rastreabilidade do fio máquina tratado | E11: Aço errado - mistura | F11: 10 | H11: Identificação do FM tratado fora do padrão | I11: Exigência de duas etiquetas | J11: 2 | K11: Fagulhamento 100% do FM tratado no abastecimento da máquina | L11: 7 | M11: =F11*J11*L11 -> 140
D12: Identificação errada | E12: Aço errado - mistura | F12: 10 | G12: (CC) | H12: Fornecedor enviou o rolo com identificação errada | I12: De acordo com procedimentos de Monlevade. (verificar quais controles são realizados) | J12: 2 | K12: Fagulhamento na expedição | L12: 8 | M12: =PRODUCT(F12,J12,L12) -> 160
C13: Receber matéria-prima sem danos mecânicos | D13: Receber matéria-prima com danos mecânicos | E13: Barras com defeito superficial | F13: 7 | H13: Não identificação do defeito no momento do recebimento | I13: Padrão de defeitos na área de recebimento | J13: 6 | K13: Conferência do check-list e auditoria de recebimento | L13: 7 | M13: =PRODUCT(F13,J13,L13) -> 294
C14: Manter matéria-prima sem danos mecânicos | D14: Matéria-prima com danos mecânicos | E14: Barras com defeito superficial | F14: 7 | H14: Contato entre as espiras | I14: Utilização de veículo próprio para rolos | J14: 6 | K14: Conferência do check-list | L14: 7 | M14: =F14*J14*L14 -> 294 | T14: =IF(Q14="","",Q14*R14*S14)
H15: Atrito do fio máquina com o berço de transporte | I15: Exigência de manta de proteção para transporte com base emborrachadas | J15: 6 | K15: Conferência do check-list | L15: 7 | M15: =F14*J14*L14 -> 294 | T15: =IF(Q15="","",Q15*R15*S15)
A16: 2 | B16: Armazenar rolos de FM | C16: Manter FM com qualidade | D16: Falta de Proteção | E16: matéria-prima com abrasão ou arranhões | F16: 7 | H16: Contato entre superfícies | I16: Utilização da proteção na lança das empilhadeiras | J16: 6 | K16: Conferência do check-list | L16: 7 | M16: =IF(F16="","",F16*J16*L16) -> 294 | T16: =IF(Q16="","",Q16*R16*S16)
N17: Efetuar a mudança do material base da proteção do ariete das empilhadeiras, substituindo a borracha (Novo material: Nylon de alta resistência) Revisar plano de manutenção preventivo incluindo no check-list a verificação da proteção de nylon do ariete da empilhadeira - (PLA202509GPSA0003) | O17: Jorge Rodrigues Jorge Rodrigues | P17: 19/08/2025 19/08/2025 | Q17: 7 | R17: 5 | S17: 7 | T17: =Q17*R17*S17 -> 245
D20: Manuseio e empilhamento irregular | E20: Criação de defeitos de manuseio | F20: 7 | H20: Pilha c/ mais de 3 rolos. Contato entre superfícies. | I20: Instruções para manuseio e empilhamento | J20: 6 | K20: Auditoria dos estoques | L20: 7 | M20: =IF(F20="","",F20*J20*L20) -> 294 | T20: =IF(Q20="","",Q20*R20*S20)
D21: Rolos mal calçados | E21: Rolo tombado | F21: 7 | H21: Falta da fixação ou mal mal fixado | I21: Posicionar o rolo corretamente nos berços de proteção. | J21: 4 | K21: Conferência do check-list | L21: 7 | M21: =F21*J21*L21 -> 196 | T21: =Q21*R21*S21 -> 0
A23: 3 | B23: Programar fabricação | C23: Programar a fabricação (sequenciamento) conforme lista técnica e planejamento de carteira | D23: Verificar com logística
D24: Matéria-prima programada errada | E24: Fabricação de material fora do especificado | F24: 6 | H24: Material com erro no cadastro | I24: Verificação das características do material ao cadastrar | J24: 2 | K24: Consistência do programa informatizado | L24: 5 | M24: =IF(F24="","",F24*J24*L24) -> 60 | T24: =Q24*R24*S24 -> 0
A25: 4 | B25: Abastecer máquina | C25: Garantir o abastecimento do material (aço e bitola) conforme especificado | D25: Abastecer o rolo de FM com material (aço/bitola) diferente do especificado. | E25: Quebra e redução da vida útil de peças do equipamento. | F25: 8 | H25: Programação do rolo errado | I25: Transformação da ordem planejada em ordem de produção é feita via sistema, conforme roteiro e lista técnica | J25: 2 | K25: SAP | L25: 2 | M25: =IF(F25="","",F25*J25*L25) -> 32 | T25: =Q25*R25*S25 -> 0
E26: Mistura de material | F26: 10 | G26: (CC) | H26: Abastecimento do rolo errado | I26: Trava no sistema MES | J26: 3 | K26: Fagulhamento na expedição | L26: 6 | M26: =IF(F26="","",F26*J26*L26) -> 180
E27: Mistura de material | F27: 10 | G27: (CC) | H27: Abastecimento do rolo errado | I27: Leitor código de barras | J27: 3 | K27: Leitor código de barras | L27: 4 | M27: =IF(F27="","",F27*J27*L27) -> 120
H28: Fornecedor enviou o rolo com identificação errada | I28: De acordo com procedimentos de Monlevade. | J28: 2 | K28: Fagulhamento na expedição | L28: 6 | M28: =F27*J28*L28 -> 120
C29: Matéria-prima sem oxidação aparente | D29: Matéria-prima com oxidação aparente | E29: Porosidade no produto acabado | F29: 4 | H29: Tempo elevado de estocagem do material no pátio | I29: FIFO automático SAP para matéria-prima. | J29: 2 | K29: Inspeção qualitativa | L29: 7 | M29: =IF(F29="","",F29*J29*L29) -> 56
C30: Matéria-prima sem defeito superficial | D30: Abastecer o equipamento com matéria-prima com defeito superficial | E30: Barras com defeito superficial | F30: 7 | H30: Movimentação e estocagem do fio máquina incorretamente | I30: Posicionar o rolo corretamente nos berços de proteção. Verificação dos arietes. | J30: 3 | K30: Inspeção qualitativa | L30: 7 | M30: =IF(F30="","",F30*J30*L30) -> 147 | T30: 84
C31: Roleta de abastecimento de FM sem arestas cortantes | D31: Roleta com arestas cortantes | E31: Barras com defeito superficial | F31: 7 | H31: Contato do FM com a roleta | I31: Revistimento da roleta com borracha | J31: 6 | K31: Inspeções qualitativas | L31: 7 | M31: =IF(F31="","",F31*J31*L31) -> 294 | T31: =Q31*R31*S31 -> 0
A32: 5 | B32: Pré-Endireitar matéria-prima | C32: Pré-endireitamento da matéria-prima para alívio de tensões | D32: Defeito superficial da matéria-prima | E32: Barras com defeito superficial. | F32: 7 | H32: Aperto excessivo das roldanas | I32: De acordo com procedimentos específicos do SIG. | J32: 7 | K32: Inspeção por corrente parasita | L32: 4 | M32: =F32*J32*L32 -> 196 | N32: Inserir no check list de inspeção de pré uso a necessidade de verificação das roldanas do pré-endireitado (PLA202510GPSA0007) | O32: Laissa 10/10/2025 | P32: 45940 | Q32: 7 | R32: 6 | S32: 4 | T32: =Q32*R32*S32 -> 168
F33: 7 | H33: Folga das roldanas | J33: 6 | K33: Inspeção por corrente parasita | L33: 4 | M33: =IF(F33="","",F33*J33*L33) -> 168
F34: 7 | H34: Aderência de material nas roldanas | J34: 6 | K34: Inspeção por corrente parasita | L34: 4 | M34: =IF(F34="","",F34*J34*L34) -> 168
D35: Pré-endireitamento ineficiente | E35: Barras com empeno fora da tolerância (7) Defeito Superficial (7) | F35: 7 | H35: Roldana Quebrada | I35: Check-list de inspeção | J35: 3 | K35: Inspeção Visual | L35: 8 | M35: =IF(F35="","",F35*J35*L35) -> 168 | N35: Inserir no check list de verificação a necessidade de inspeção visual das roldanas (PLA202504GPSA0001) | O35: Marcio Cristeli 31/03/2025 | P35: 45747 | Q35: 7 | R35: 3 | S35: 7 | T35: =Q35*R35*S35 -> 147
H36: Roldanas desalinhadas | I36: Regulagem do pré-endireitador | J36: 4 | K36: Medição de empeno da barra | L36: 6 | M36: =F35*J36*L36 -> 168
D37: Rolo em cruz não atuando | E37: Barras com empeno fora da tolerância | F37: 7 | H37: Rolamento travado | I37: Manutenção periódica de acordo com o RCM. | J37: 4 | K37: Medição de empeno da barra | L37: 5 | M37: =IF(F37="","",F37*J37*L37) -> 140 | T37: =Q37*R37*S37 -> 0
T38: =Q38*R38*S38 -> 0
A39: 6 | B39: Decapar matéria-prima | C39: Deixar o FM isento de carepa para a trefilação e criar porosidade mínima para melhor aderência do oleo lubrificante. Controlar a amperagem com foco na vazâo da granalha. | D39: Matéria-prima muito decapada | E39: Porosidade excessiva no produto acabado. | F39: 6 | H39: Excesso de vazão de granalha | I39: Desarme automático do bi-metálico | J39: 3 | K39: Verificação do amperímetro conforme procedimento | L39: 7 | M39: =IF(F39="","",F39*J39*L39) -> 126
H40: Caracteristica da granalha fora da especificação. | I40: Análise da granalha após o fornecimento | J40: 3 | M40: =F39*J40*L39 -> 126 | T40: =PRODUCT(Q40:S40) -> 0
D41: Matéria-prima pouco decapada | E41: Manchas superficiais na barra | F41: 6 | H41: Pouca vazão de granalha | I41: Amperímetro da máquina | J41: 3 | K41: Verificação do amperímetro conforme procedimento | L41: 7 | M41: =IF(F41="","",F41*J41*L41) -> 126 | T41: =PRODUCT(Q41,R41,S41) -> 0
H42: Caracteristica da granalha fora da especificação. | I42: Análise da granalha após o fornecimento | J42: 3 | K42: Inspeção qualitativa após decapadora | M42: =F41*J42*L41 -> 126
D43: Matéria-prima com oxidação | E43: Porosidade excessiva no material | F43: 6 | H43: Tempo elevado de estocagem do material no pátio | I43: Item de Controle de estoque de matéria-prima: FM>75 dias e FIFO sistema | J43: 3 | K43: Inspeção qualitativa após decapadora | L43: 7 | M43: =F43*J43*L43 -> 126
...

Sheet Plano de Controle - Schumag
F1: ArcelorMittal - Sabará Diretoria de Trefilação | AN1: CÓDIGO: | AR1: =Capa!P1 -> DTREF SGI DD 0007
AN2: REVISÃO: | AR2: =Capa!P2 -> 22
AN3: DATA REVISÃO: | AR3: =Capa!P3 -> 45954
AN4: PÁGINA: | AR4: 4 de 8
A5: PLANO DE CONTROLE
A6: OPERAÇÃO | F6: Máquina - Dispositivo | J6: CARACTERÍSTICA | T6: MÉTODOS | AN6: Controle Registro | AR6: Plano de Reação
A7: Nº | B7: Descrição | J7: Tipo | K7: Produto | P7: Processo | T7: Especificação de Engenharia | X7: Meio de Controle | AC7: MSA | AD7: Doc.Técnica Referência | AH7: Amostra
AH8: Tamanho | AK8: Frequência
A9: 1 | B9: Receber e inspecionar FM | F9: Carreta tipo colmeia, rolos protegidos por revestimento de borracha | K9: Aspecto físico | T9: Condiçoes do material, estado físico (oxidação e riscos) e forma do rolo (embalagem e identificação) | X9: Inspeção visual | AC9: X | AD9: De acordo com procedimentos específicos do SIG. | AH9: Todos os rolos | AK9: 1 | AN9: Check List no Recebimento | AR9: Segregar material e avisar a Supervisão
J10: (CC) | K10: Composição química | T10: Conformidade com o Certificado de Qualidade | X10: Conferencia do Certificado de Qualidade | AD10: Certificado de Qualidade | AH10: Molas Amortecedores | AK10: 1 por dia | AN10: Planilha Controle de Verificação | AR10: Segregar material e contactar fornecedor para correção do Certiifcado de Qualidade
P11: Conferencia de NF | T11: Nota Fiscal em conformidade com a etiqueta | X11: Fazer a entrada da nota fiscal via coletor | AD11: De acordo com procedimentos. | AH11: Todos os rolos | AK11: 1 | AN11: Sistema informatizado - SAP | AR11: Segregar material e avisar a Supervisão
P12: Inspecionar FM | T12: FM sem danos mecânicos | X12: Auditoria | AD12: Conforme sistemática estabelecida | AH12: Descarregamento | AK12: Mensal | AN12: Formulário de auditoria | AR12: Segregar e acionar fornecedor
A13: 2 | B13: Armazenar rolos de FM | F13: Pátio de armazenamento específico | K13: Rolos identificados conforme local de estocagem. | T13: Identificação conforme | X13: Inventário rotativo | AD13: De acordo com pocedimento operacional | AH13: Todos carregamentos | AK13: 1 | AN13: Sistema informatizado - SAP | AR13: Reposicionar material conforme identificação.
P14: Empilhamento dos rolos no local adequado | T14: Empilhamento de 3 rolos sobre berços de madeira e separadores de papelão conforme especificado. | X14: Acompanhamento do supervisor durante a estocagem | AD14: De acorodo com Pocedimento operacional | AH14: Rolos de Fio Máquina | AK14: 1 | AN14: S/ Registro | AR14: Remanejar FM
A15: 3 | B15: Programar Fabricação | F15: Micro Computador | K15: FM disponível no sistema | T15: Conforme especificação técnica do cadastro do material no SAP. | X15: Sistema Informatizado - SAP | AD15: *Sistema Informatizado - SAP *MES | AH15: Todo FM | AK15: 1 | AN15: Sistema Informatizado - SAP | AR15: Revisar cadastro de produto no sistema informatizado
P16: Elaboração de Ordem de Produção | T16: Programação conforme planejamento de produção | X16: Conferencia de geração da OP | AD16: Sistema Informatizado - SAP | AH16: Toda OP | AK16: 1 | AN16: Sistema Informatizado - SAP | AR16: Revisão na programação do material.
A17: 4 | B17: Abastecer Máquima | F17: Empilhadeira e ponte rolante | K17: Tipo de aço, bitola, corrida e número do rolo | T17: Conformidade com especificação técnica da OP | X17: Coerência da OP e a etiqueta do FM | AD17: De acordo com procedimentos do SIG | AH17: 1 amostra por rolo de FM | AK17: 100 % | AN17: Sistema informatizado - Sap | AR17: Segregar material e avisar supervisão
K18: Materia prima com nível de oxidação e aspecto superficial e ambalagem aceitáveis | T18: Oxidação, riscos e condições de embalagem | X18: Inspeção Visual | AC18: X | AD18: De acordo com procedimentos do SIG | AH18: Todos os rolos de FM | AK18: 100 % | AN18: Sistema informatizado - SAP | AR18: Segregar material e avisar supervisão
J19: (CC) | P19: Etiqueta legível e não danificada | T19: Rolos conforme solicitado na OP | X19: - Leitor ótico - Sistema informatizado | AD19: De acordo com procedimentos específicos do SIG. | AH19: Todos os rolos de FM | AK19: 100 % | AN19: Sistema informatizado - SAP | AR19: Segregar material e avisar supervisão
A20: 5 | B20: Pré-Endireitar Materia Prima | F20: Pré-endireitadores | K20: FM desempenado | T20: FM endireitado | X20: Passar pela guia (funil) de entrada da decapadora | AD20: De acordo com procedimentos específicos do SIG. | AH20: Todos os rolos de FM | AK20: 100 % | AN20: Sem registro | AR20: Conforme procedimentos
K21: FM isento de defeitos superficiais | T21: FM isento de defeitos superficiais | X21: Inspeção por corrente parasita | AD21: De acordo com procedimentos específicos do SIG. | AH21: Todos os rolos de FM | AK21: 100 % | AN21: Sem registro | AR21: Conforme procedimentos
P22: Ajuste das roldanas dos pré-endireitadores | T22: Roldanas ajustadas conforme FM em processo | X22: Check list das peças | AD22: De acordo com procedimentos específicos do SIG. | AH22: Toda OP | AK22: 100 % | AN22: Sistema informatizado - MES | AR22: Conforme procedimentos
P23: Nível de desgaste e limpeza das roldanas | T23: Roldanas em estado de uso sem afetar a qualidade superficial do FM | X23: Roldanas sem desgaste | AD23: De acordo com procedimentos específicos do SIG. | AH23: Todos os FM | AK23: 100 % | AN23: Sem registro | AR23: Conforme procedimentos
A24: 6 | B24: Decapar Materia Prima | F24: Decapadora | K24: Superfície limpa e sem manchas | T24: Carepa removida | X24: Inspeção visual | AD24: De acordo com procedimentos específicos do SIG. | AH24: Todos os FM | AK24: 100 % | AN24: Sem registro | AR24: Segregar material e avisar supervisão
P25: Abastecimento de granalha por controle da amperagem | T25: Amperímetro entre 20 e 37 ampéres | X25: Amperímetro | AD25: De acordo com procedimentos específicos do SIG. | AH25: Durante a troca de turno | AK25: 100 % | AN25: Controle da variável pelo check list do MES | AR25: Checar decapadora, Checar fio máquina, Checar granalha e informar a supervisão.
T26: Schumag 907 entre 10 a 37 ampéres
A27: 7 | B27: Trefilar matéria prima | F27: Bloco trefilador | P27: Fieria lubrificada | T27: lubrificação adequada para evitar quebra | X27: Inspeção visual | AD27: De acordo com procedimentos específicos do SIG. | AH27: Troca de turno ou interrupção/fechamento da válvula | AK27: 1 | AN27: Check list MES | AR27: Checar nível do óleo, funcionamento da bomba e informar a supervisão
K28: Material conforme bitola | T28: Material com qualidade superficial conforme tolerância de bitola. | X28: Micrômetro | AC28: X | AD28: De acordo com procedimentos específicos do SIG. | AH28: 1 amostra de barra | AK28: 100% | AN28: Certificado de Qualidade | AR28: Segregar material e avisar a supervisão
P29: Redução do material conforme requerido no processo | T29: Matéria-prima requerida no processo | X29: Verificação de FM e fieira para o processo | AD29: De acordo com procedimentos específicos do SIG. | AH29: Toda OP | AK29: 100% toda parada de linha | AN29: S/ Registro | AR29: Regulagem da máquina e avisar supervisão
A30: 8 | B30: Inspecionar Barras por Corrente Parasita | F30: Circograph | K30: Barras com defeito longitudinal dentro do especificado | T30: Ganho em Db's de acordo com catálogo do material | X30: Informação no monitor da inspeção online | AD30: Informação na biblioteca do equipamento | AH30: Todas as barras | AK30: 100 % | AN30: Base de dados do sistema de inspeção | AR30: Avisar a supervisão Informar a supervisão e segregar material
P31: Aferição na inspeção automática | T31: Realizar a atividade de aferição conforme procedimento operacional | X31: Informações conforme relatório de aferições | AD31: De acordo com procedimento específicos do SIG | AH31: Todos os equipamentos de inspeção | AK31: 1x a mês | AN31: Conforme relatório das aferições | AR31: Segregar material
P32: Ajuste do equipamento de inspeção automática | T32: Ajuste conforme procedimento operacional | X32: Informação no monitor da inspeção online | AD32: De acordo com procedimentos específicos do SIG. | AH32: Todas as OP's | AK32: 100 % | AN32: Base de dados do sistema de inspeção | AR32: Regular sensibilidade conforme defeito detectado
F33: Defectomat | K33: Barras com defeito longitudinal dentro do especificado | T33: Ganho em Db's de acordo com catálogo do material | X33: Informação no monitor da inspeção online | AD33: Informação na biblioteca do equipamento | AH33: Todas as barras | AK33: 100 % | AN33: Base de dados do sistema de inspeção | AR33: Avisar a supervisão Informar a supervisão e segregar material
P34: Aferição na inspeção automática | T34: Realizar a atividade de aferição conforme procedimento operacional | X34: Informações conforme relatório de aferições | AD34: De acordo com procedimento específicos do SIG | AH34: Todos os equipamentos de inspeção | AK34: 1x a mês | AN34: Conforme relatório das aferições | AR34: Segregar material
P35: Ajuste do equipamento de inspeção automática | T35: Ajuste conforme procedimento operacional | X35: Informação no monitor da inspeção online | AD35: De acordo com procedimentos específicos do SIG. | AH35: Todas as OP's | AK35: 100 % | AN35: Base de dados do sistema de inspeção | AR35: Regular sensibilidade conforme defeito detectado
F36: Desmagnetizador | K36: Barras com magnetismo dentro do especificado | T36: Conforme Ordem de Produção | X36: Magnetismo | AD36: De acordo com procedimentos específicos do SIG. | AH36: Todos os lotes | AK36: 100 % toda parada de linha | AN36: Sistema informatizado - MES | AR36: Informar a supervisão e segregar material
P37: _Regulagem do desmagnetizador _Verificar funcionamento | T37: Conforme Ordem de Produção | X37: Magnetismo | AD37: De acordo com procedimentos específicos no SIG. | AH37: _Todos os lotes _Toda parada de linha | AK37: 100 % | AN37: Sistema informatizado - MES | AR37: Acionar a manutenção e supervisores
A38: 9 | B38: Cortar barras - schumags | F38: Tesoura | K38: Barra no comprimento especificado | T38: Conforme Ordem de produção | X38: Trena | AC38: X | AD38: De acordo com procedimentos específicos no SIG. | AH38: 1 barra | AK38: cada 500kg | AN38: Sistema informatizado - MES | AR38: Segregar material e avisar a supervisão
K39: Sem rebarba | T39: Barras sem rebarba | X39: Inspeção Visual | AC39: X | AD39: De acordo com procedimentos específicos no SIG. | AH39: Todo lote | AK39: 1 | AN39: Sistema informatizado - MES | AR39: Substituição da Bucha de Corte
P40: Setup do comprimento | T40: Corte no comprimento especificado conforme Ordem de Produção | X40: Trena | AC40: X | AD40: De acordo com procedimentos específicos no SIG. | AH40: 1 barra | AK40: cada 500kg | AN40: Sistema informatizado - MES | AR40: Ajuste do sistema de corte
...

Sheet Severidade
D1: ArcelorMittal - Sabará Diretoria de Trefilação | N1: CÓDIGO: | P1: =Capa!P1 -> DTREF SGI DD 0007
N2: REVISÃO: | P2: =Capa!P2 -> 22
N3: DATA REVISÃO: | P3: =Capa!P3 -> 45954
N4: PÁGINA: | P4: 5 de 8
A5: SEVERIDADE DO EFEITO NO PRODUTO

Sheet Ocorrência
D1: ArcelorMittal - Sabará Diretoria de Trefilação | N1: CÓDIGO: | P1: =Capa!P1 -> DTREF SGI DD 0007
N2: REVISÃO: | P2: =Capa!P2 -> 22
N3: DATA REVISÃO: | P3: =Capa!P3 -> 45954
N4: PÁGINA: | P4: 6 de 8
A5: OCORRÊNCIA DE CAUSA - PFMEA

Sheet Detecção
D1: ArcelorMittal - Sabará Diretoria de Trefilação | N1: CÓDIGO: | P1: =Capa!P1 -> DTREF SGI DD 0007
N2: REVISÃO: | P2: =Capa!P2 -> 22
N3: DATA REVISÃO: | P3: =Capa!P3 -> 45954
N4: PÁGINA: | P4: 7 de 8
A5: PROBABILIDADE DE DETECÇÃO POR CONTROLE DE PROCESSO

Sheet Histórico de Revisão
C1: ArcelorMittal - Sabará Diretoria de Trefilação | D1: CÓDIGO: | F1: =Capa!P1 -> DTREF SGI DD 0007
D2: REVISÃO: | F2: =Capa!P2 -> 22
D3: DATA REVISÃO: | F3: =Capa!P3 -> 45954
D4: PÁGINA: | F4: 8 de 8
A5: HISTÓRICO DE REVISÕES
B8: Revisão | C8: Alteração Realizada
B9: 37 | C9: *Plano de Controle: Para melhor visualização, detalhamento e compreensão, as características de produto e processo foram separadas em linhas distintas para cada operação. *FMEA: Ações realizadas na operação "Retificar Barras", como troca das réguas de bronze e instalação de iluminária na máquina. *FMEA: Ações realizadas na operação "Cortar Barras", como troca dos rolos de bronze por rolos de nylon.
B10: 38 | C10: *FMEA: Ações relacionadas a reclamação de oxidação das barras - Item 7 "Trefilar Matéria Prima" Requisito: "Óleo lubrificante isento de contaminação". Alterado também no Item: "10 - Endireitar / Polir e Inspecionar Barras" Requisito: "Óleo lubrificante isento de contaminação". *FMEA End. e Peeling: Conforme AA017/2018: Item 5 - "Pré-Endireitar/Skin Pass/Twisting rolls" Inserido novo modo de falha: Utilização dos rolos de laminação incorreto (Linhas 33,35,36 e37) *FMEA: Conforme plano de ação auditoria da Marelli 2017: alterado a definição da severidade (6) no modo de falha "empenamento" para os produtos Magneti Marelli define em nota 7 devido o amortecedor ficar inoperante com a falha apresentada.
B11: 39 | C11: *FMEA: Ações relacionadas a reclamação pintura de feixe - Itens 12 Cortar barras prensas (linha 140) e 16- Expedir barras (linha 172) *FMEA: Ações relacionadas a reclamação da fratura da mola helicoidal TK - Item 12 Cortar barras prensas (linhas 136 a 139) * Alterado em todas as abas a utilização do SIG como ferramenta para gestão de documentos, e não o SGI
B12: 40 | C12: *FMEA: Ações relacionadas a IATF Auditoria interna NC3 2019 - A sistemática de rastreabilidade de medição não encontra-se eficaz - Produção. Inserido no FMEA Schumag (Item 10) e no End e Pee (Item 07), para o modo de falha Instrumentos de medição não calibrados, a Ação de revisar o texto do MES para preenchimento dos códigos dos instrumentos de medição. *FMEA Schumag Inspecionar FM, inserido a ação para requisito matéria prima com qualidade a respeito do novo cargo do operador de processo responsável por inspecionar o FM
B13: 41 | C13: *FMEA Schumag: Ação relacionado a NC 3 Externa - Sistemática de produto NC - Retroalimentado com um novo requisito (Materia prima dentro de suas especificações de qualidade" para os processo "Retificar Barras (caso necessário)" e para o processo "Cortar Barra - prensas". Além do requisito, outros campos também foram inseridos do FMEA (Ações, Modo de Falha, Efeito, mecanismo de falhar e etc.) Linha 108 e 121 (Aproximadamente)
B14: 42 | C14: *Retroalimentado o FMEA e Plano de controle conforme NC IATF Auditoria Externa NC4 2019 - Falha na sistemática de calibração/verificação *Retroalimentado o FMEA conforme RNC da Rassini 078/19 - Dados da Etiqueta para os processos de Trefilar e Retifica com novo modo de Falha "Falha no cadastro do material"
B15: 43 | C15: *Retroalimentado o FMEA conforme RNC da Magneti Marelli - nº 15/19 - Jun/19 - Vazamento de óleo e gás * Retroalimentado o FMEA conforme RNC da Sogefi Argentina AA Sogefi Argentina Agosto/2019 QRQC N°464 - Empeno
B16: 44 | C16: *Retroalimentado o FMEA conforme NC da Marelli - AA Material empenado Magneti Marelli - B201900057364 - Setembro/2019 *Retroalimentado o FMEA conforme NC da Marelli - AA Material Magnetizado Magneti Marelli -B201900057363 - Setembro/2019 *Retroalimentado o FMEA conforme auditoria de produto realizado no corte pelo Cássio Martins
B17: 45 | C17: *Revisão da equipe principal
B18: 46 | C18: * Revisão das ações recomendadas
B19: 47 | C19: * Criação do FMEA Corte, Plano de controle Corte e Fluxo de processo corte
B20: 49 | C20: * Revisão do FMEA e Plano de controle para as atividades da retífica
... B24: 53 | C24: * Capacitar e recilclar os operadores nas questões relacionadas a medição dos produtos. Revisar o procedimento operacional acrescentando a verificação de comprimento com a trena a laser a cada troca de turno e ou troca de programa. * Revisão do FMEA e Plano de controle processo de fagulhamento * Melhoria no sistema MÊS - limpar dados
B25: Rev01 | C25: Adicionado o gaussímetro como instrumento de medição de magnetismo. Medições de ovalização Quantidade de cintas metálicas que impactam no empeno das barras.
B26: Rev02 | C26: Ações relacionadas ao empeno de barras trefiladas. Ações relacionadas a corte de barras no comprimento incorreto.
C29: Acrescentar verificação de lacres durante abastecimento e reação
C30: Acrescentar a área específica para retirada das etiquetas
C31: Limpar roleta durante troca
C32: Sequênciamento com cores diferentes para os materiais
B33: REV:07 | C33: RO 202227984 PLA202301AT0001 1) Realizar manutenção corretiva do cilindro do batente de corte 2) Realizar lubrificação das máquinas de acordo com o calendário 3) Inserir no alerta do sistema MES e na Ordem de Produção a mensagem de "Verificar topo e colar etiqueta de topo verificado" 4) Inserir as etiquetas de topo verificado nos feixes produzidos 5) Desenvolver novo sistema de batente para evitar as falhas de acionamento
B34: REV:08 | C34: RO 202339186 PLA202305AT0004 Estabelecer no procedimento operacional (GPSA FBA PO 0057) a obrigatoriedade de descarte das 4 primeiras em todo ínicio de processo e após a ocorrência de falhas elétricas Corrigir a falha no sistema elétrico da unidade de transporte da trefila
B35: REV:09 | C35: Revisão periódica
B36: REV:10 | C36: Revisão periódica
B37: REV:11 | C37: Revisão periódica
B38: REV:12 | C38: Revisão periódica
B39: REV:13 | C39: Revisão periódica
B40: REV:14 | C40: Revisão periódica
B41: REV:15 | C41: Revisão do modo de falha "barra magnetizada"
B42: REV:16 | C42: Revisão do modo de falha "barra com empeno fora de tolerância"
B43: REV:17 | C43: Revisão do modo de falha "Falha de lubrificação nos trenós"
B44: REV:18 | C44: Revisão do modo de falha "Desgaste da Peça de Naylon do Troller"
... B46: Rev: 20 | C46: Revisão do Modo de Falha " Roldanas de Frenagem travadas"

Sheet Lições Aprendidas
A2: Item | B2: Etapa | C2: Modo de Falha Potencial | D2: Causa(s) Potenciais / Mecanismo de Falha | E2: Ação Recomendada | F2: Responsabilidade Data de conclusão prevista | G2: Ações realizadas Data de conclusão
A3: It
A4: 1 | B4: Receber e inspecionar FM | C4: Falta de identificação | D4: Perda da etiqueta de identificação no manuseio | E4: Etiquetas rompidos ou com etiqueta improvisada, não receber o FM e acionar imediatamente a logísitca e/ou equipe do laboratório, para realizar o bloqueio. | F4: Alexandre | G4: 44878
D5: Lacres rompidos ou etiquetas improvisadas | E5: Se o FM estiver com os lacres das duas etiquetas rompidos ou com etiqueta improvisada, não receber o FM e acionar imediatamente a logísitca e/ou equipe do laboratório, para realizar o bloqueio. | F5: Alexandre | G5: 44878
C6: Identificação errada | D6: Fornecedor enviou o rolo com identificação errada
C7: Receber matéria-prima com danos mecânicos | D7: Não identificação do defeito no momento do recebimento
C8: Matéria-prima com danos mecânicos | D8: Contato entre as espiras | E8: Realização de Plano de Experimentos (banho de sabão) objetivando diminuir os defeitos mecânicos causados pela compactação do FM na AM Monlevade. | F8: Márcio Cristeli 31/12/14 | G8: Banho de sabão implementado em 31/12/14
D9: Atrito do fio máquina com o berço de transporte | E9: Criar sistemática para recebimento de matéria prima. | F9: Márcio Cristeli 29/06/2018 | G9: Realizar auditorias periódicas, além da conferência dos Certificados de Qualidade.
A10: 2 | B10: Armazenar rolos de FM | C10: Falta de Proteção | D10: Contato entre superfícies | E10: 1) Vulcanização e revestimento em borracha dos arietes das empilhadeiras. 2) Efetuar a troca da proteção de borrachas das empilhaderias de Sabará | F10: 1) Márcio Cristeli 01/12/14 2) Carolina Siqueira 18/08/19 | G10: 1) Revestimento implementado em 26/09/14 2) ok
E11: 1) Definir local fixo para acondicionamentos, identificados e demarcados para rolos fio maquina especifico para CK 2) Revisar procedimento de acondicionamento de rolos fio-máquina contemplando o local especifico (GPSA LOG PO 0074). 3) Treinar envolvidos no procedimento (GPSA LOG PO 0074) | F11: 1) Geraldo Mol - 31/03/21 2) Bruna Melo - 09/04/21 | G11: Foi definido o local específico com as devidas proteções
E12: Revisar plano de manutenção preventivo incluindo no check list o padrão de aceitabilidade da proteção de borracha da ariete da empilhadeira de Sabará. | F12: Carolina Siqueira 30/09/19 | G12: Foi revisado o plano de manutenção preventivo
E13: Criar um padrão fotográfico para inspeção de fio máquina via procedimento da equipe | F13: Jeveson Batista | G13: Foi revisado o procedimento da equipe
C14: Manuseio e empilhamento irregular | D14: Pilha c/ mais de 3 rolos. Contato entre superfícies. | E14: Treinamento de concientização e boas práticas na movimentação e estocagem de FM. | F14: Márcio Cristeli 31/12/2014 | G14: Treinamento realizado em 13/05/14 e 19/11/14
C15: Rolos mal calçados | D15: Falta da fixação ou mal mal fixado | E15: Treinamento de concientização e boas práticas na movimentação e estocagem de FM. | F15: Eduardo Lopes 15/12/15 | G15: Manutenção realizada em 15/12/2015
E16: Substituição dos berços de madeiras localizados nas entradas das máquinas de trefilar por um sistema com tapetes e ancoragem de borracha. Melhorar a fixação dos berços de estocagem do FM. | F16: Eduardo Lopes 31/10/15 Túlio 06/05/22 | G16: Substituição dos berços realizada em 29/09/2015
A17: 3 | B17: Programar fabricação | C17: Matéria-prima programada errada | D17: Material com erro no cadastro | E17: Padronizar programação, não permitindo trocas alternando o tipo de aço com a mesma bitola | F17: Maycon 24/11/22 | G17: 44889
A18: 4 | B18: Abastecer máquina | C18: Abastecer o rolo de FM com material (aço/bitola) diferente do especificado. | D18: Programação do rolo errado | E18: Criar bloqueio no MES, evitando a inserção de dados fora do especificado para o produto. | F18: Thiago Salles 20/04/2017 | G18: Realizado em 17/04/2017
D19: Abastecimento do rolo errado | E19: Implementar trava no sistema impedindo a digitação manual do consumo de matéria prima. Detalhar no procedimento cada passo do abastecimento do fio máquina Instalar a cabine de abastecimento ao lado do local de abastecimento do fio máquina Criar comitê de rastreabilidade Colocar no sequenciamento cores diferentes para os materiais, Aparecer o pop-up na tela de alerta quando houver a troca de OP. instalar trava no sistema para que o time da operação não retorne para um OP aberta sem o aval da supervisão | F19: Bruna 06/09/22 Geraldo Mol 10/12/22 Geraldo Mol 28/11/22 Geraldo Mol 28/11/22 Bruna 02/12/22 | G19: Bruna 06/09/22 Geraldo Mol 10/12/22 Geraldo Mol 28/12/22 Geraldo Mol 28/11/22 Bruna 02/01/23
D20: Abastecimento do rolo errado | E20: Desenvolver um plano de substituição dos coletores defasados (levantamento das especificações). | F20: Thiago Salles 09/09/16 | G20: Realizado em 09/09/16
D21: Fornecedor enviou o rolo com identificação errada | E21: Estudar a compra de um espectrômetro portátil para detecção/separação de misturas. | F21: Fernando Muradas 31/01/2018 | G21: Estudo realizado porém sem modificações
C22: Matéria-prima com oxidação aparente | D22: Tempo elevado de estocagem do material no pátio | E22: NA | F22: NA | G22: NA
C23: Abastecer o equipamento com matéria-prima com defeito superficial | D23: Movimentação e estocagem do fio máquina incorretamente | E23: Manutenção dos arietes empilhadeira | F23: Willian(Brasiltec) 12/2018 | G23: Realizado em 12/2018
C24: Roleta com arestas cortantes | D24: Contato do FM com a roleta | E24: 1) Revestir a roleta com borracha protetora ( RO 202342682 ) 2) Inserir no plano de manutenção a inspeção da roleta de abastecimento do rolo de fio máquina ( RO 202342682 ) 3)Inserir no plano de manutenção a inspeção da roleta de abastecimento do rolo de fio máquina ( RO 202342682 ) | F24: 1) Tulio 20/06/23 2) Tulio 20/06/23 3) Tulio 20/06/23 | G24: Realizado 20/06/23
A25: 5 | B25: Pré-Endireitar matéria-prima | C25: Defeito superficial da matéria-prima | D25: Aperto excessivo das roldanas | E25: Nenhuma | F25: NA | G25: NA
D26: Folga das roldanas | E26: Nenhuma | F26: NA | G26: NA
D27: Aderência de material nas roldanas | E27: Nenhuma | F27: NA | G27: NA
C28: Pré-endireitamento ineficiente | D28: Roldanas desalinhadas | E28: NA | F28: NA | G28: NA
C29: Rolo em cruz não atuando | D29: Rolamento travado | E29: Regular o rolo em cruz | F29: Gilberto 02/07/2015 | G29: Rolo em cruz regulado em 02/10/2015
E30: Incluir no RCM a verificação do rolo em cruz | F30: Gilberto 02/10/2015 | G30: Inclusão realizada em 02/10/2015
A31: 6 | B31: Decapar matéria-prima | C31: Matéria-prima muito decapada | D31: Excesso de vazão de granalha | E31: NA | F31: NA | G31: NA
D32: Caracteristica da granalha fora da especificação. | E32: fazer um estudo da qualidade atual da granalha atualizada . Estamos como sentimento que a granalha esta destruindo muito fácil . contatar fornecedor e fazer uma avaliação em laboratório. | F32: Vinicius 04/2018 | G32: Realizado o estudo e apresentado para o fornecedor para adequação
C33: Matéria-prima pouco decapada | D33: Pouca vazão de granalha | E33: 1) Revisar o Check list pré uso da Máquina 908. 2) Revisar procedimento da Máquina 908, inserindo a necessidade do preenchimento da variável do amperímetro no cleck list. | F33: 1) Carol Siqueira 14/07/23 2) Ana Barcelos 14/07/23 | G33: 1) concluído 14/07/23 2) concluído 31/07/23
D34: Caracteristica da granalha fora da especificação. | E34: Fazer um estudo da qualidade atual da granalha atualizada . Estamos como sentimento que a granalha esta destruindo muito fácil . contatar fornecedor e fazer uma avaliação em laboratório. | F34: Vinicius 04/2018 | G34: Realizado o estudo e apresentado para o fornecedor para adequação
C35: Matéria-prima com oxidação | D35: Tempo elevado de estocagem do material no pátio | E35: NA | F35: NA | G35: NA
A36: 7 | B36: Trefilar matéria-prima | C36: Aderência de material na fieira | D36: Má lubrificação
D37: Má decapagem
C38: Barra apresentando martensita na região da superfície | D38: Atrito do fio-máquina com a fieira durante o processo de trefilação devido à baixa lubrificação | E38: Solicitar ao fabricante o “arredondamento” da quina na região do ângulo de entrada da fieira. | F38: Márcio Cristeli 20/05/2016 | G38: Solicitação realizada em 20/05/2016
E39: Incluir observação no cadastro do produto para isenção de marcas/riscos helicoidais na barra trefilada. | F39: Fernando Muradas 20/04/2016 | G39: Observação incluída em 20/04/2016
E40: Inserir no check list de pré uso do equipamento 906 o alerta para verificar o nível do reservatório de óleo da fieira nas trocas de turno. | F40: Paulo Celso 15/07/2020 | G40: Realizado
E41: Alterar procedimento e treinar operadores para controle do fluxo ideal de óleo, após interrupção/fechamento da válvula. | F41: Bruna Melo 03/08/2020 | G41: Realizado
...
